{"nbformat":4,"nbformat_minor":0,"metadata":{"colab":{"provenance":[],"authorship_tag":"ABX9TyNYvta/ymI4NWQLoeThP4OS"},"kernelspec":{"name":"python3","display_name":"Python 3"},"language_info":{"name":"python"}},"cells":[{"cell_type":"markdown","source":["Общая идея, заложенная в основу **метода обработки исключений**, такая: программный код, в котором теоретически может возникнуть ошибка, выделяется специальным образом – \"берется на контроль\". Если при выполнении \"контролируемого\" кода возникает ошибка, то выполнение кода останавливается и автоматически создается объект-исключение, содержащий описание возникшей ошибки. Если при выполнении этого программного кода ошибка не возникает, то ничего особенного не происходит."],"metadata":{"id":"Xm2hOgJ4Mi10"}},{"cell_type":"code","source":["#@title Для обработки исключительных ситуаций в языке Python используется конструкция **try-except**\n","\n","try:\n","    # контролируемый код\n","except:\n","    # код обработки ошибки (исключения)"],"metadata":{"id":"sfidphkJMzxb"},"execution_count":null,"outputs":[]},{"cell_type":"markdown","source":["Если при выполнении кода в блоке try ошибка не возникла, то код обработки ошибки (исключения) в блоке except выполняться не будет. Если при выполнении кода в блоке try возникла ошибка, то выполнение кода trу блока прекращается, и выполняется код обработки ошибки (исключения) в блоке except. После этого управление передается следующей команде после конструкции try-except."],"metadata":{"id":"URpTI6drM1rb"}},{"cell_type":"code","source":["#Пример: \n","try:\n","    num1 = int(input())\n","    num2 = int(input())\n","    print('Частное чисел равно', num1 / num2)\n","except:\n","    print('Вы ввели некорректные данные!')\n","\n","print('Работа программы завершена!')\n"],"metadata":{"id":"RZHbw3LWM9ad"},"execution_count":null,"outputs":[]},{"cell_type":"code","source":["#@title Конструкция для обработки нескольких исключений:\n","try:\n","    # контролируемый код\n","except тип_ошибки_1:\n","    # код обработки ошибки (исключения)\n","except тип_ошибки_2:\n","    # код обработки ошибки (исключения)\n","except тип_ошибки_n:\n","    # код обработки ошибки (исключения)\n"],"metadata":{"id":"kRIOGclmNCVL"},"execution_count":null,"outputs":[]},{"cell_type":"code","source":["#Пример: на вход подается номер месяца(т.е число из диапазона [1;12]), программа должна вывести его название\n","from calendar import month_name \n","\n","#print(list(month_name)) #mounth_name - список месяцев ['', 'January', 'February', 'March' ... ]\n","months = dict(enumerate(month_name))  # создаем словарь, где ключ - номер месяца, а значение - его название\n","del months[0] #удаляем пару 0 : ''\n","\n","m = input()\n","try:\n","    print(months[int(m)])\n","except KeyError:\n","    print('Введено число из недопустимого диапазона') #т.е введеное число не входит в диапазон [1;12]\n","except ValueError:\n","    print('Введено некорректное значение') #т.е объект не смог привестись к типу int"],"metadata":{"id":"5Zt0b0HwO6_J"},"execution_count":null,"outputs":[]},{"cell_type":"markdown","source":["**Основные типы исключений:**\n","*   **IndexError**: возникает, когда индекс (например, для элемента списка) указан  неправильно (выходит за границы допустимого диапазона)\n","*   **KeyError**: возникает при неверно указанном ключе словаря\n","*   **NameError**: возникает, если не удается найти переменную с некоторым названием\n","*   **SyntaxError**: возникает при наличии в исходном коде синтаксических ошибок\n","*   **TypeError**: возникает при несоответствии типов, когда для обработки требуется значение определенного типа, а передается значение другого типа\n","*   **FileNotFoundError**: возникает при открытии несуществующего файла\n","*   **ValueError**: возникает, когда в функцию передается аргумент с неподдерживаемым значением\n","*   **ZeroDivisionError**: возникает при попытке выполнить деление на ноль"],"metadata":{"id":"eUVBegOZRDD-"}},{"cell_type":"markdown","source":["Важно понимать разницу между типами исключений TypeError и ValueError.\n","\n","Исключение **TypeError** возникает, когда встроенная функция (или операция) применяется к объекту неподходящего типа.\n","Пример: print('beegeek' + 2022) приводит к возникновению исключения TypeError\n","\n","Исключение **ValueError** возникает, когда встроенная функция (или операция) получает аргумент правильного типа, но с неподходящим значением\n","Приведенный ниже код:\n","num = int('beegeek')\n","приводит к возникновению исключения ValueError."],"metadata":{"id":"XHO8Hac8RcoT"}},{"cell_type":"code","source":["#@title Общий шаблон инструкции try-except\n","try:\n","    # контролируемый код\n","except тип_ошибки_1:\n","    # код обработки ошибки (исключения)\n","except тип_ошибки_2:\n","    # код обработки ошибки (исключения)\n","...\n","except тип_ошибки_n:\n","    # код обработки ошибки (исключения)\n","else:\n","    # код для случая, если ошибки не было\n","finally:\n","    # код, который выполняется всегда\n"],"metadata":{"id":"KGwmDTiXRwqx"},"execution_count":null,"outputs":[]},{"cell_type":"markdown","source":["Помимо блоков try и except, в инструкции try-except может также использоваться необязательный блок else. **Блок else** размещается после последнего ехсерt блока и содержит программный код, который выполняется только в том случае, если при выполнении кода в trу блоке ошибок (исключений) не было."],"metadata":{"id":"JptvU0T0R4C6"}},{"cell_type":"markdown","source":["**Блок finally** размещается после последнего ехсерt блока, либо после блока else, если он присутствует, и содержит программный код, который выполняется в любом случае, независимо от того, возникла ошибка (исключение) при выполнении кода trу блока или нет. Инструкции внутри блока finally будут выполнены, даже если блок try содержит break, continue, return"],"metadata":{"id":"iWMH2TmxR_3b"}},{"cell_type":"code","source":["#Пример: работу контекстного менеджера with можно примерно описать с помощью конструкции try-except-finaly\n","\n","#Протокол гарантирует выполнение завершающих действий (например, закрытие файла) вне зависимости от того, произошла ошибка (исключение) внутри блока кода или нет. \n","with open('data.txt', 'r', encoding='utf-8') as file:\n","    text = file.read()\n","\n","#Равнозначный код\n","try:\n","    file = open('data.txt', 'r', encoding='utf-8')\n","    try:\n","        text = file.read()\n","    finally:\n","        file.close()\n","except:\n","    pass #отсутсвие операции"],"metadata":{"id":"BunuicSFTF2d"},"execution_count":null,"outputs":[]},{"cell_type":"markdown","source":["**pass** - оператор, равноценный отсутствию операции. В ходе исполнения данного оператора ничего не происходит, поэтому он может использоваться в качестве заглушки в тех местах, где это синтаксически необходимо"],"metadata":{"id":"MojXipNoT-00"}},{"cell_type":"markdown","source":["**РАБОТА С ИСКЛЮЧЕНИЕМ КАК С ОБЪЕКТОМ**\n","\n","Если нужен доступ к сгенерированному исключению как к объекту, то используется специальный синтаксис."],"metadata":{"id":"LPxv5GGvUL1L"}},{"cell_type":"code","source":["try:\n","    nums = [10, 5, 20, 25]\n","    print(nums[100])\n","except (KeyError, IndexError) as err:    # записываем сгенерированное исключение в переменную err\n","    print(err) #в переменную err попадает объект типа IndexError\n","    print(type(err))"],"metadata":{"id":"JPCgyeONUbY6"},"execution_count":null,"outputs":[]},{"cell_type":"markdown","source":["Если при обработке всех исключений одним блоком except мы хотим получить доступ к объекту исключения, то нужно явно указать его тип."],"metadata":{"id":"1E70dnPnUvVn"}},{"cell_type":"code","source":["try:\n","    х = 1 / 0\n","except Exception as err:\n","    print(err)"],"metadata":{"id":"8j0LTa8JUx8J"},"execution_count":null,"outputs":[]},{"cell_type":"code","source":["#Пример: в коде возникает какая-то ошибка, хотим узнать ее тип\n","\n","numbers = list(filter(int, ['1', '2', '3', '4', '5']))\n","#тк испольузется функция filter, а не map в numbers лежит список строк\n","try:\n","    total = sum(numbers) #sum не работает со списком строк\n","    print(total)\n","except Exception as err:\n","    print(type(err)) #поэтому возникает ошибка TypeError\n"],"metadata":{"colab":{"base_uri":"https://localhost:8080/"},"id":"cikoW3WjU8c_","executionInfo":{"status":"ok","timestamp":1678633114678,"user_tz":-240,"elapsed":4,"user":{"displayName":"Kate Chikareva","userId":"06959987387988367771"}},"outputId":"0ecb9afb-b46e-449b-aa8d-3db962edd4f9"},"execution_count":null,"outputs":[{"output_type":"stream","name":"stdout","text":["<class 'TypeError'>\n"]}]},{"cell_type":"markdown","source":["**ВОЗБУЖДЕНИЕ ИСКЛЮЧЕНИЙ**\n","\n","Мы можем заставить наш код возбудить исключение вручную с помощью  оператора **raise**. \n","\n","В качестве аргумента оператор raise использует экземпляр класса, унаследованного от Exception. Класс указывает на тип исключения, а аргумент, передаваемый конструктору этого исключения, обычно описывает подробности возникновения исключительной ситуации.\n","\n","Возбуждаемые пользователем исключения перехватываются тем же способом, что и исключения, которые возбуждает интерпретатор Python.\n","\n"],"metadata":{"id":"79Kh3klWVvFA"}},{"cell_type":"code","source":["try:\n","    raise IndexError('ошибочка')             # возбуждение исключения вручную\n","except Exception as err:\n","    print(err)\n","    print(type(err)) "],"metadata":{"id":"r33NqooFWjAa"},"execution_count":null,"outputs":[]},{"cell_type":"markdown","source":["Конструктор исключения принимает переменное количество аргументов.\n","\n"],"metadata":{"id":"uMMP0ZMoXArc"}},{"cell_type":"code","source":["try:\n","    raise ValueError('Ой', 'Произошла ошибка')\n","except ValueError as e:\n","    print(e)"],"metadata":{"id":"iIsgXQh1XE9i"},"execution_count":null,"outputs":[]},{"cell_type":"code","source":["try:\n","    raise ValueError('oops')\n","except ValueError as e:\n","    print(e)\n","    print(e.args)\n","    print(type(e.args))"],"metadata":{"id":"wTRPZtZsoWti","executionInfo":{"status":"ok","timestamp":1678638163179,"user_tz":-240,"elapsed":1092,"user":{"displayName":"Kate Chikareva","userId":"06959987387988367771"}},"outputId":"e6bce026-9104-4ad2-a16d-7bd0b0391080","colab":{"base_uri":"https://localhost:8080/"}},"execution_count":null,"outputs":[{"output_type":"stream","name":"stdout","text":["oops\n","('oops',)\n","<class 'tuple'>\n"]}]},{"cell_type":"markdown","source":["**ПОЛЬЗОВАТЕЛЬСКИЕ ИСКЛЮЧЕНИЯ**"],"metadata":{"id":"CZAi6CQl5ESj"}},{"cell_type":"markdown","source":["В Python можно создавать собственные типы исключений. Такая практика позволяет увеличить гибкость процесса обработки ошибок в рамках той предметной области, для которой написана программа.\n","\n","Для создания собственного типа исключения необходимо создать класс, являющийся потомком (наследником) одного из уже существующего типа исключения. Самым верным вариантом является класс Exception."],"metadata":{"id":"urI4Bsbm5Kj2"}},{"cell_type":"code","source":["class NegativeAgeError(Exception):\n","    pass\n","#Создается новый тип исключенияNegativeAgeError, который является потомком класса Exception. \n","#Класс Exception содержит весь необходимый функционал, позволяющий работать с исключениями, поэтому в большинстве случаев достаточно создать пустой класс, который является потомком класса Exception. \n","#Теперь мы можем работать с типом исключения NegativeAgeError, как с любым встроенным."],"metadata":{"id":"-ljpw7re5Tzf"},"execution_count":null,"outputs":[]},{"cell_type":"code","source":["try:\n","    print('Введите свой возраст')\n","    age = int(input())\n","    if age < 0:\n","        raise NegativeAgeError('Возраст не может быть отрицательным')\n","    print('Ваш возраст равен', age)\n","except ValueError:\n","    print('Возраст должен быть числом')\n","except NegativeAgeError as e:\n","    print(e)\n","#при вводе некорректных значений приводит к возбуждению соответствующих типов исключений:\n","#ValueError – при нечисловых значениях \n","#NegativeAgeError – при отрицательных числовых значениях"],"metadata":{"id":"pqFAXMbv5Yma"},"execution_count":null,"outputs":[]}]}